Workbook
Name ExternalData_1: 初始表!$A$1:$L$39
Name ExternalData_2: 初始表!#REF!
Name ExternalData_3: 初始表!$A$40:$L$45
Name ExternalData_4: 初始表!$A$46:$L$54
Name ExternalData_5: 初始表!$A$55:$L$58
Name ExternalData_6: 初始表!$A$59:$P$179
Name ExternalData_7: 初始表!#REF!
Name ExternalData_8: 初始表!$A$180:$L$263
Name ExternalData_9: 初始表!$A$264:$L$265
Name ExternalData_10: 初始表!$A$266:$L$340
Name ExternalData_1: '参考表-catagory'!$A$1:$D$75

Sheet 初始表
A1: product_id | B1: std_name_cn | C1: std_name_en | D1: hs_code | E1: synonyms(中文) | F1: scenarios(中文) | G1: technical_terms(中文) | H1: exclusion_terms(中文) | I1: synonyms(英文) | J1: scenarios(英文) | K1: technical_terms(英文) | L1: exclusion_terms(英文)
A2: =_xlfn.LET(_xlpm.pname,_xlfn.XLOOKUP(D2,'参考表-商品编码与name'!$A:$A,'参考表-商品编码与name'!$B:$B,""),_xlpm.seq,COUNTIF($D$2:D2,D2),_xlpm.pname&"_"&TEXT(_xlpm.seq,"00000")) -> Electric Motors_00001 | B2: 异步电动机 | C2: Asynchronous Motor | D2: 8501 | E2: 感应电机,交流异步电机,鼠笼式电机,Induction Motor,IM,AC Induction Motor,三相异步电机,单相异步电机,Squirrel Cage Motor,Wound Rotor Motor,工业电机,通用电机,IEC标准电机,NEMA电机,国标电机,Y系列电机,Y2电机,YX3高效电机,防爆异步电机,变频异步电机 | F2: 驱动风机,水泵动力,工业传动,机床主轴 | G2: 功率(kW),转速(rpm),防护等级(IP),绝缘等级F级,效率等级(IE3/IE4) | H2: 同步电机,伺服电机,直流电机,步进电机,磁阻电机 | I2: Induction Motor,AC Asynchronous Motor,Squirrel-Cage Motor,Wound Rotor Motor,Industrial AC Motor,General Purpose Motor,IEC Standard Motor,NEMA Frame Motor,GB Standard Motor,Y Series Motor,Y2 Motor,YX3 High-Efficiency Motor,Explosion-Proof Induction Motor,VFD-Compatible Motor | J2: Driving fans,Powering water pumps,Industrial transmission,Machine tool spindle drive | K2: Power (kW),Speed (rpm),IP Rating,Insulation Class F,Efficiency Class (IE3/IE4) | L2: Synchronous Motor,Servo Motor,DC Motor,Stepper Motor,Switched Reluctance Motor
A3: =_xlfn.LET(_xlpm.pname,_xlfn.XLOOKUP(D3,'参考表-商品编码与name'!$A:$A,'参考表-商品编码与name'!$B:$B,""),_xlpm.seq,COUNTIF($D$2:D3,D3),_xlpm.pname&"_"&TEXT(_xlpm.seq,"00000")) -> Electric Motors_00002 | B3: 直流电动机 | C3: DC Motor | D3: 8501 | E3: 有刷直流电机,Brushed DC Motor,永磁直流电机,PMDC Motor,串励电机,并励电机,他励电机,复励电机,小型直流马达,玩具电机,微型直流电机,12V直流电机,24V直流电机,汽车雨刮电机,电动车窗电机 | F3: 电动车驱动,玩具动力,小型设备调速 | G3: 额定电压(V),转矩(N·m),空载转速,效率%,电枢电阻 | H3: 无刷电机,步进电机,交流电机,伺服电机,发电机 | I3: Brushed DC Motor,Permanent Magnet DC Motor (PMDC),Series Wound Motor,Shunt Wound Motor,Separately Excited Motor,Compound Wound Motor,Miniature DC Motor,Toy Motor,Micro DC Motor,12V DC Motor,24V DC Motor,Automotive Wiper Motor,Power Window Motor | J3: Electric vehicle propulsion,Toy power source,Speed control for small appliances | K3: Rated Voltage (V),Torque (N·m),No-load Speed,Efficiency %,Armature Resistance | L3: Brushless DC Motor (BLDC),Stepper Motor,AC Motor,Servo Motor,Generator
A4: =_xlfn.LET(_xlpm.pname,_xlfn.XLOOKUP(D4,'参考表-商品编码与name'!$A:$A,'参考表-商品编码与name'!$B:$B,""),_xlpm.seq,COUNTIF($D$2:D4,D4),_xlpm.pname&"_"&TEXT(_xlpm.seq,"00000")) -> Electric Motors_00003 | B4: 伺服电机 | C4: Servo Motor | D4: 8501 | E4: 伺服马达,AC伺服电机,DC伺服电机,闭环控制电机,精密伺服,工业伺服,数控伺服,机器人关节电机,高响应电机,带编码器电机,Servo Drive Unit,全数字伺服,脉冲控制电机,模拟量伺服,总线型伺服（EtherCAT/CANopen） | F4: 数控机床定位,机器人关节控制,自动化装配 | G4: 编码器分辨率（PPR）,响应时间(ms),最大转矩,惯量比,过载能力(3倍) | H4: 普通电机,步进电机,变频电机,异步电机,力矩电机 | I4: Servo Motor,Servo Actuator,AC Servo Motor,DC Servo Motor,Closed-Loop Motor,Precision Servo,Industrial Servo,CNC Servo,Robotic Joint Motor,High-Response Motor,Encoder-Equipped Motor,Servo Drive System,Fully Digital Servo,Pulse-Controlled Servo,Analog Servo,Bus-Enabled Servo (EtherCAT/CANopen) | J4: CNC machine tool positioning,Robotic joint control,Automated assembly | K4: Encoder Resolution (PPR),Response Time (ms),Peak Torque,Inertia Ratio,Overload Capacity (3x) | L4: Standard Induction Motor,Stepper Motor,VFD Motor,Asynchronous Motor,Torque Motor
A5: =_xlfn.LET(_xlpm.pname,_xlfn.XLOOKUP(D5,'参考表-商品编码与name'!$A:$A,'参考表-商品编码与name'!$B:$B,""),_xlpm.seq,COUNTIF($D$2:D5,D5),_xlpm.pname&"_"&TEXT(_xlpm.seq,"00000")) -> Electric Motors_00004 | B5: 步进电机 | C5: Stepper Motor | D5: 8501 | E5: 步进马达,脉冲电机,开环电机,两相步进,五相步进,混合式步进电机(HB),永磁式步进(PM),反应式步进(VR),28BYJ,42步进,57步进,86步进,NEMA17,NEMA23,NEMA34,微步步进,细分驱动电机 | F5: 3D打印定位,CNC雕刻,打印机送纸 | G5: 步距角(°),保持转矩,相数,驱动电流,空载启动频率 | H5: 伺服电机,直流电机,同步电机,无刷电机,直线电机 | I5: Stepper Motor,Step Motor,Pulse Motor,Open-Loop Motor,2-Phase Stepper,5-Phase Stepper,Hybrid Stepper (HB),Permanent Magnet Stepper (PM),Variable Reluctance Stepper (VR),28BYJ,42mm Stepper,57mm Stepper,86mm Stepper,NEMA17,NEMA23,NEMA34,Microstepping Motor,Subdivision Drive Motor | J5: 3D printing positioning,CNC engraving,Printer paper feeding | K5: Step Angle (°),Holding Torque,Number of Phases,Drive Current,Max Starting Frequency | L5: Servo Motor,DC Motor,Synchronous Motor,BLDC Motor,Linear Motor
A6: =_xlfn.LET(_xlpm.pname,_xlfn.XLOOKUP(D6,'参考表-商品编码与name'!$A:$A,'参考表-商品编码与name'!$B:$B,""),_xlpm.seq,COUNTIF($D$2:D6,D6),_xlpm.pname&"_"&TEXT(_xlpm.seq,"00000")) -> Electric Motors_00005 | B6: 发电机 | C6: Generator | D6: 8501 | E6: 交流发电机,Alternator,发电装置,同步发电机,三相发电机,柴油发电机（整机除外）,汽油发电机（整机除外）,水轮发电机,风力发电机,备用电源发电机 | F6: 备用电源供电,水电站发电,车载充电 | G6: 输出功率(kVA),频率(Hz),电压(V),励磁方式,相数 | H6: 电动机,变压器,整流器 | I6: AC Generator,Alternator,Power Generation Unit,Synchronous Generator,Three-Phase Generator,Diesel Generator (unit excluded),Gasoline Generator (unit excluded),Hydro Generator,Wind Turbine Generator,Standby Generator | J6: Backup power supply,Hydropower generation,On-board charging | K6: Output Power (kVA),Frequency (Hz),Voltage (V),Excitation Method,Number of Phases | L6: Electric Motor,Transformer,Rectifier
A7: =_xlfn.LET(_xlpm.pname,_xlfn.XLOOKUP(D7,'参考表-商品编码与name'!$A:$A,'参考表-商品编码与name'!$B:$B,""),_xlpm.seq,COUNTIF($D$2:D7,D7),_xlpm.pname&"_"&TEXT(_xlpm.seq,"00000")) -> Generating Sets_00001 | B7: 柴油发电机组 | C7: Diesel Generator Set | D7: 8502 | E7: 柴油发电机,柴发机组,DG Set,静音柴油发电机,移动式柴油发电机,集装箱式发电机组,船用柴油发电机组,应急柴油发电机 | F7: 应急供电,工地用电,海岛离网供电 | G7: 额定功率(kW),油耗(L/h),噪音(dB),启动方式(电/手),冷却方式 | H7: 汽油发电机,UPS电源,逆变器 | I7: Diesel Generator,Diesel Genset,DG Set,Silent Diesel Generator,Mobile Diesel Generator,Containerized Generator Set,Marine Diesel Generator,Emergency Diesel Generator | J7: Emergency power supply,Construction site power,Off-grid island power | K7: Rated Power (kW),Fuel Consumption (L/h),Noise Level (dB),Starting Method (Electric/Manual),Cooling Method | L7: Gasoline Generator,UPS,Inverter
A8: =_xlfn.LET(_xlpm.pname,_xlfn.XLOOKUP(D8,'参考表-商品编码与name'!$A:$A,'参考表-商品编码与name'!$B:$B,""),_xlpm.seq,COUNTIF($D$2:D8,D8),_xlpm.pname&"_"&TEXT(_xlpm.seq,"00000")) -> Generating Sets_00002 | B8: 汽油发电机组 | C8: Gasoline Generator Set | D8: 8502 | E8: 汽油发电机,便携式发电机,Petrol Generator,小型汽油发电机,家用汽油发电机,数码变频汽油发电机 | F8: 露营供电,家庭备用,小型商铺用电 | G8: 输出功率(kW),油箱容量(L),THD<5%,重量(kg),燃油类型 | H8: 柴油发电机,太阳能逆变器,蓄电池组 | I8: Gasoline Generator,Portable Generator,Petrol Generator,Small Gasoline Generator,Household Gasoline Generator,Inverter Gasoline Generator | J8: Camping power,Home backup,Small shop power | K8: Output Power (kW),Fuel Tank Capacity (L),THD<5%,Weight (kg),Fuel Type | L8: Diesel Generator,Solar Inverter,Battery Bank
A9: =_xlfn.LET(_xlpm.pname,_xlfn.XLOOKUP(D9,'参考表-商品编码与name'!$A:$A,'参考表-商品编码与name'!$B:$B,""),_xlpm.seq,COUNTIF($D$2:D9,D9),_xlpm.pname&"_"&TEXT(_xlpm.seq,"00000")) -> Motor Parts_00001 | B9: 电机定子 | C9: Stator | D9: 8503 | E9: 定子铁芯,定子绕组,电机静子,定子组件,定子线圈,硅钢片定子,叠压定子,浸漆定子 | F9: 电机维修,绕线更换,电磁装配 | G9: 槽槽数,绕组匝数,绝缘漆类型,叠厚(mm),铁芯外径 | H9: 转子,电枢,换向器 | I9: Stator Core,Stator Winding,Stationary Part,Stator Assembly,Stator Coil,Silicon Steel Stator,Laminated Stator,Varnished Stator | J9: Motor repair,Winding replacement,Electromagnetic assembly | K9: Number of Slots,Turns per Coil,Insulation Varnish Type,Stack Length (mm),Core Outer Diameter | L9: Rotor,Armature,Commutator
A10: =_xlfn.LET(_xlpm.pname,_xlfn.XLOOKUP(D10,'参考表-商品编码与name'!$A:$A,'参考表-商品编码与name'!$B:$B,""),_xlpm.seq,COUNTIF($D$2:D10,D10),_xlpm.pname&"_"&TEXT(_xlpm.seq,"00000")) -> Motor Parts_00002 | B10: 电机转子 | C10: Rotor | D10: 8503 | E10: 电枢,转子铁芯,旋转部件,转子组件,鼠笼转子,绕线转子,动平衡转子,轴承转子 | F10: 动平衡测试,轴承更换,电机重绕 | G10: 外径(mm),动平衡等级,材料(硅钢片),轴径,长度 | H10: 定子,端盖,碳刷 | I10: Armature,Rotor Core,Rotating Part,Rotor Assembly,Squirrel Cage Rotor,Wound Rotor,Dynamic Balanced Rotor,Bearing Mounted Rotor | J10: Dynamic balancing test,Bearing replacement,Motor rewinding | K10: Outer Diameter (mm),Balance Grade,Material (Silicon Steel),Shaft Diameter,Length | L10: Stator,End Bell,Carbon Brush
A11: =_xlfn.LET(_xlpm.pname,_xlfn.XLOOKUP(D11,'参考表-商品编码与name'!$A:$A,'参考表-商品编码与name'!$B:$B,""),_xlpm.seq,COUNTIF($D$2:D11,D11),_xlpm.pname&"_"&TEXT(_xlpm.seq,"00000")) -> Motor Parts_00003 | B11: 电刷 | C11: Carbon Brush | D11: 8503 | E11: 碳刷,集电刷,换向器刷,电机电刷,滑环电刷,石墨电刷,铜基石墨刷 | F11: 电机维护,滑环接触,电流传导 | G11: 接触电阻(mΩ),磨损率,电流密度(A/cm²),硬度,长度 | H11: 电极,接线端子,导电膏 | I11: Carbon Brush,Collector Brush,Commutator Brush,Motor Brush,Slip Ring Brush,Graphite Brush,Copper-Graphite Brush | J11: Motor maintenance,Slip ring contact,Current conduction | K11: Contact Resistance (mΩ),Wear Rate,Current Density (A/cm²),Hardness,Length | L11: Electrode,Terminal Block,Conductive Grease
A12: =_xlfn.LET(_xlpm.pname,_xlfn.XLOOKUP(D12,'参考表-商品编码与name'!$A:$A,'参考表-商品编码与name'!$B:$B,""),_xlpm.seq,COUNTIF($D$2:D12,D12),_xlpm.pname&"_"&TEXT(_xlpm.seq,"00000")) -> Transformers_00001 | B12: 电力变压器 | C12: Power Transformer | D12: 8504 | E12: 配电变压器,油浸变压器,干式变压器,三相变压器,单相变压器,箱式变电站变压器,电力系统变压器 | F12: 变电站输电,工厂配电,电网升压降压 | G12: 额定容量(kVA),电压比,阻抗电压%,冷却方式,绝缘等级 | H12: 稳压器,电抗器,互感器 | I12: Distribution Transformer,Oil-Immersed Transformer,Dry-Type Transformer,Three-Phase Transformer,Single-Phase Transformer,Pad-Mounted Transformer,Power System Transformer | J12: Substation transmission,Factory power distribution,Grid voltage step-up/down | K12: Rated Capacity (kVA),Voltage Ratio,Impedance Voltage %,Cooling Method,Insulation Class | L12: Voltage Regulator,Reactor,Instrument Transformer
A13: =_xlfn.LET(_xlpm.pname,_xlfn.XLOOKUP(D13,'参考表-商品编码与name'!$A:$A,'参考表-商品编码与name'!$B:$B,""),_xlpm.seq,COUNTIF($D$2:D13,D13),_xlpm.pname&"_"&TEXT(_xlpm.seq,"00000")) -> Transformers_00002 | B13: 开关电源 | C13: Switching Power Supply | D13: 8504 | E13: SMPS,AC-DC电源,DC-DC转换器,开关模式电源,高频开关电源,LED驱动电源,工业电源,医疗电源,通信电源,适配器 | F13: 电子设备供电,LED驱动,通信设备电源 | G13: 输出电压(V),纹波(mV),效率%,负载调整率,MTBF(小时) | H13: 线性电源,电池充电器,逆变器 | I13: Switching Mode Power Supply (SMPS),AC-DC Power Supply,DC-DC Converter,High-Frequency SMPS,LED Driver Power Supply,Industrial Power Supply,Medical Grade PSU,Telecom Power Supply,AC Adapter | J13: Powering electronic devices,LED lighting driver,Telecom equipment power | K13: Output Voltage (V),Ripple (mV),Efficiency %,Load Regulation,MTBF (hours) | L13: Linear Power Supply,Battery Charger,Inverter
... A81: =_xlfn.LET(_xlpm.pname,_xlfn.XLOOKUP(D81,'参考表-商品编码与name'!$A:$A,'参考表-商品编码与name'!$B:$B,""),_xlpm.seq,COUNTIF($D$2:D81,D81),_xlpm.pname&"_"&TEXT(_xlpm.seq,"00000")) -> Storage Media_00003 | B81: 固态硬盘 | C81: Solid State Drive | D81: 8523 | E81: SATA SSD,NVMe SSD,M.2固态硬盘,企业级SSD,便携SSD | F81: 电脑升级,服务器存储,高速启动,笔记本扩容,外置存储 | G81: 容量(TB),顺序读写(GB/s),TBW寿命,接口协议,缓存大小 | H81: 机械硬盘,混合硬盘,主板,散热片,数据线 | I81: SATA SSD,NVMe SSD,M.2 SSD,Enterprise SSD,Portable SSD | J81: PC upgrade,Server storage,Fast boot,Laptop expansion,External storage | K81: Capacity (TB),Sequential Read/Write (GB/s),TBW Endurance,Interface Protocol,Cache Size | L81: HDD,SSHDD,Motherboard,Heatsink,Data Cable
A82: =_xlfn.LET(_xlpm.pname,_xlfn.XLOOKUP(D82,'参考表-商品编码与name'!$A:$A,'参考表-商品编码与name'!$B:$B,""),_xlpm.seq,COUNTIF($D$2:D82,D82),_xlpm.pname&"_"&TEXT(_xlpm.seq,"00000")) -> Storage Media_00004 | B82: 机械硬盘 | C82: Hard Disk Drive | D82: 8523 | E82: 3.5英寸HDD,2.5英寸HDD,监控硬盘,NAS硬盘,企业级硬盘 | F82: 台式机存储,笔记本扩容,监控录像,NAS阵列,数据中心 | G82: 容量(TB),转速(RPM),缓存(MB),接口(SATA),年负载量 | H82: SSD,电源,数据线,硬盘盒,RAID卡 | I82: 3.5 HDD | J82: 2.5" HDD | K82: Surveillance HDD | L82: NAS HDD | M82: Enterprise HDD" | N82: Desktop storage,Laptop expansion,Security recording,NAS array,Data center | O82: Capacity (TB),RPM,Cache (MB),Interface (SATA),Annual Workload | P82: SSD,Power Supply,Data Cable,HDD Enclosure,RAID Card
A83: =_xlfn.LET(_xlpm.pname,_xlfn.XLOOKUP(D83,'参考表-商品编码与name'!$A:$A,'参考表-商品编码与name'!$B:$B,""),_xlpm.seq,COUNTIF($D$2:D83,D83),_xlpm.pname&"_"&TEXT(_xlpm.seq,"00000")) -> Storage Media_00005 | B83: 光盘 | C83: Optical Disc | D83: 8523 | E83: CD-R/DVD-R,CD-RW/DVD-RW,Blu-ray Disc,可打印光盘,档案级光盘 | F83: 软件分发,电影刻录,数据归档,照片备份,法律证据保存 | G83: 读取速度(X),染料类型,反射层,保存期限,认证标准 | H83: 光驱,标签打印机,存储盒,刻录软件,防静电袋 | I83: CD-R/DVD-R,CD-RW/DVD-RW,Blu-ray Disc,Printable Disc,Archival Disc | J83: Software distribution,Movie burning,Data archiving,Photo backup,Legal evidence | K83: Read Speed (X),Dye Type,Reflective Layer,Shelf Life,Certification Standards | L83: Optical Drive,Label Printer,Storage Case,Burning Software,Anti-Static Bag
A84: =_xlfn.LET(_xlpm.pname,_xlfn.XLOOKUP(D84,'参考表-商品编码与name'!$A:$A,'参考表-商品编码与name'!$B:$B,""),_xlpm.seq,COUNTIF($D$2:D84,D84),_xlpm.pname&"_"&TEXT(_xlpm.seq,"00000")) -> Flat Panel Display Modules_00001 | B84: LCD显示屏 | C84: LCD Display Module | D84: 8524 | E84: TFT液晶屏,工业LCD,车载中控屏,医疗显示屏,POS机屏幕 | F84: 仪器仪表显示,车载信息娱乐,医疗设备界面,收银终端,工业控制面板 | G84: 分辨率,亮度(cd/m²),视角(°),响应时间,工作温度 | H84: 背光板,驱动IC,触摸屏,控制板,外壳 | I84: TFT LCD Panel,Industrial LCD,Car Infotainment Screen,Medical Display,POS Screen | J84: Instrument display,Car infotainment,Medical interface,Checkout terminal,Industrial HMI | K84: Resolution,Brightness (cd/m²),Viewing Angle (°),Response Time,Operating Temperature | L84: Backlight,Driver IC,Touch Panel,Control Board,Housing
A85: =_xlfn.LET(_xlpm.pname,_xlfn.XLOOKUP(D85,'参考表-商品编码与name'!$A:$A,'参考表-商品编码与name'!$B:$B,""),_xlpm.seq,COUNTIF($D$2:D85,D85),_xlpm.pname&"_"&TEXT(_xlpm.seq,"00000")) -> Flat Panel Display Modules_00002 | B85: OLED显示屏 | C85: OLED Display Module | D85: 8524 | E85: AMOLED屏,柔性OLED,透明OLED,曲面OLED,小尺寸OLED | F85: 高端手机显示,可穿戴设备,透明橱窗,曲面电视,智能手表 | G85: 对比度,响应时间(μs),寿命(h),色域,功耗 | H85: 驱动IC,封装材料,偏光片,触控层,电路板 | I85: AMOLED Panel,Flexible OLED,Transparent OLED,Curved OLED,Small OLED | J85: Premium phone display,Wearable devices,Transparent window,Curved TV,Smartwatch | K85: Contrast Ratio,Response Time (μs),Lifetime (h),Color Gamut,Power Consumption | L85: Driver IC,Encapsulation,Polarizer,Touch Layer,PCB
A86: =_xlfn.LET(_xlpm.pname,_xlfn.XLOOKUP(D86,'参考表-商品编码与name'!$A:$A,'参考表-商品编码与name'!$B:$B,""),_xlpm.seq,COUNTIF($D$2:D86,D86),_xlpm.pname&"_"&TEXT(_xlpm.seq,"00000")) -> Flat Panel Display Modules_00003 | B86: 触摸屏 | C86: Touch Panel | D86: 8524 | E86: 电容式触摸屏,电阻式触摸屏,红外触摸屏,表面声波屏,多点触控屏 | F86: 自助终端,教育白板,工业控制,零售POS,智能家居面板 | G86: 触控点数,透光率%,表面硬度,响应速度,防水等级 | H86: 显示屏,控制器,玻璃盖板,连接线,校准软件 | I86: Capacitive Touch Panel,Resistive Touch Panel,IR Touch Panel,SAW Touch Panel,Multi-Touch Screen | J86: Self-service kiosk,Educational whiteboard,Industrial control,Retail POS,Smart home panel | K86: Touch Points,Transmittance %,Surface Hardness,Response Speed,Waterproof Rating | L86: Display,Controller,Cover Glass,Cable,Calibration Software
A87: =_xlfn.LET(_xlpm.pname,_xlfn.XLOOKUP(D87,'参考表-商品编码与name'!$A:$A,'参考表-商品编码与name'!$B:$B,""),_xlpm.seq,COUNTIF($D$2:D87,D87),_xlpm.pname&"_"&TEXT(_xlpm.seq,"00000")) -> Flat Panel Display Modules_00004 | B87: 电子墨水屏 | C87: E-Ink Display | D87: 8524 | E87: 黑白电子纸,彩色电子纸,柔性电子屏,超低功耗屏,货架标签屏 | F87: 电子书阅读器,智能货架标签,公交站牌,可穿戴设备,工业铭牌 | G87: 刷新率,可视角度,阳光下可读性,功耗(μW),寿命 | H87: 背板,驱动电路,保护膜,电池,无线模块 | I87: Monochrome E-Paper,Color E-Paper,Flexible E-Ink,Low-Power Display,ESL Screen | J87: E-reader,Smart shelf label,Bus stop sign,Wearable device,Industrial tag | K87: Refresh Rate,Viewing Angle,Sunlight Readability,Power Consumption (μW),Lifetime | L87: Backplane,Driver Circuit,Protective Film,Battery,Wireless Module
A88: =_xlfn.LET(_xlpm.pname,_xlfn.XLOOKUP(D88,'参考表-商品编码与name'!$A:$A,'参考表-商品编码与name'!$B:$B,""),_xlpm.seq,COUNTIF($D$2:D88,D88),_xlpm.pname&"_"&TEXT(_xlpm.seq,"00000")) -> Flat Panel Display Modules_00005 | B88: Mini LED显示屏 | C88: Mini LED Display | D88: 8524 | E88: Mini LED背光模组,直显Mini LED,高对比度屏,HDR显示屏,专业监视器屏 | F88: 高端电视,专业监视器,车载显示,AR/VR设备,广告大屏 | G88: 分区控光数,峰值亮度(nit),对比度,色域覆盖率,功耗 | H88: 驱动IC,散热系统,光学膜,控制板,电源 | I88: Mini LED Backlight,Direct View Mini LED,HDR Display,Pro Monitor Screen,Advertising Screen | J88: Premium TV,Professional monitor,Car display,AR/VR,Advertising billboard | K88: Local Dimming Zones,Peak Brightness (nit),Contrast Ratio,Color Gamut Coverage,Power Consumption | L88: Driver IC,Heat Sink,Optical Film,Control Board,Power Supply
A89: =_xlfn.LET(_xlpm.pname,_xlfn.XLOOKUP(D89,'参考表-商品编码与name'!$A:$A,'参考表-商品编码与name'!$B:$B,""),_xlpm.seq,COUNTIF($D$2:D89,D89),_xlpm.pname&"_"&TEXT(_xlpm.seq,"00000")) -> Cameras_00001 | B89: 广播电视发射机 | C89: Broadcast Transmitter | D89: 8525 | E89: FM发射机,TV发射塔设备,数字电视发射机,中波发射机,短波发射机 | F89: 无线信号覆盖,电台电视台播出,应急广播,农村广播,国际广播 | G89: 发射功率(kW),频段(MHz),调制方式,覆盖半径,冷却方式 | H89: 接收机,天线,馈线,监控系统,备用电源 | I89: FM Transmitter,TV Transmitter,Digital TV Transmitter,MW Transmitter,SW Transmitter | J89: Wireless coverage,Radio/TV broadcasting,Emergency broadcast,Rural broadcast,International broadcast | K89: Transmit Power (kW),Frequency Band (MHz),Modulation,Coverage Radius,Cooling Method | L89: Receiver,Antenna,Feeder,Monitoring System,Backup Power
A90: =_xlfn.LET(_xlpm.pname,_xlfn.XLOOKUP(D90,'参考表-商品编码与name'!$A:$A,'参考表-商品编码与name'!$B:$B,""),_xlpm.seq,COUNTIF($D$2:D90,D90),_xlpm.pname&"_"&TEXT(_xlpm.seq,"00000")) -> Cameras_00002 | B90: 摄像机 | C90: Camcorder | D90: 8525 | E90: 专业摄像机,ENG摄像机,广播级摄像机,4K摄像机,高清手持摄像机 | F90: 新闻外拍,影视制作,纪录片拍摄,体育赛事,婚礼录像 | G90: 传感器尺寸,码流(Mbps),ND滤镜,接口类型,防抖性能 | H90: 照相机,三脚架,监视器,存储卡,麦克风 | I90: Professional Camcorder,ENG Camera,Broadcast Camera,4K Camcorder,HD Handheld Camcorder | J90: News field shooting,Film production,Documentary,Sports event,Wedding video | K90: Sensor Size,Data Rate (Mbps),ND Filter,Interface Types,Image Stabilization | L90: Camera,Tripod,Monitor,Memory Card,Microphone
A91: =_xlfn.LET(_xlpm.pname,_xlfn.XLOOKUP(D91,'参考表-商品编码与name'!$A:$A,'参考表-商品编码与name'!$B:$B,""),_xlpm.seq,COUNTIF($D$2:D91,D91),_xlpm.pname&"_"&TEXT(_xlpm.seq,"00000")) -> Cameras_00003 | B91: 照相机 | C91: Digital Camera | D91: 8525 | E91: 数码单反,微单相机,卡片机,长焦相机,全景相机 | F91: 摄影创作,旅行记录,商业拍摄,野生动物,房地产展示 | G91: 像素(MP),CMOS尺寸,连拍速度,镜头卡口,ISO范围 | H91: 摄像机,闪光灯,三脚架,存储卡,滤镜 | I91: DSLR,Mirrorless Camera,Compact Camera,Superzoom Camera,360-Degree Camera | J91: Photography creation,Travel documentation,Commercial shooting,Wildlife,Real estate showcase | K91: Megapixels (MP),CMOS Sensor Size,Burst Speed,Lens Mount,ISO Range | L91: Camcorder,Flash,Tripod,Memory Card,Filter
A92: =_xlfn.LET(_xlpm.pname,_xlfn.XLOOKUP(D92,'参考表-商品编码与name'!$A:$A,'参考表-商品编码与name'!$B:$B,""),_xlpm.seq,COUNTIF($D$2:D92,D92),_xlpm.pname&"_"&TEXT(_xlpm.seq,"00000")) -> Cameras_00004 | B92: 热成像相机 | C92: Thermal Imaging Camera | D92: 8525 | E92: 手持热像仪,固定式热像仪,消防用热像仪,工业检测热像仪,建筑诊断热像仪 | F92: 电力巡检,消防救援,建筑节能,工业测温,安防监控 | G92: 分辨率,热灵敏度(mK),测温范围,帧率,镜头焦距 | H92: 普通相机,显示器,分析软件,防护箱,校准设备 | I92: Handheld Thermal Camera,Fixed Thermal Camera,Firefighting Thermal Imager,Industrial Thermal Imager,Building Diagnostic Camera | J92: Power inspection,Fire rescue,Energy audit,Industrial temperature,Security surveillance | K92: Resolution,Thermal Sensitivity (mK),Temperature Range,Frame Rate,Lens Focal Length | L92: Visible Camera,Monitor,Analysis Software,Protection Case,Calibration Device
A93: =_xlfn.LET(_xlpm.pname,_xlfn.XLOOKUP(D93,'参考表-商品编码与name'!$A:$A,'参考表-商品编码与name'!$B:$B,""),_xlpm.seq,COUNTIF($D$2:D93,D93),_xlpm.pname&"_"&TEXT(_xlpm.seq,"00000")) -> Cameras_00005 | B93: 夜视摄像机 | C93: Night Vision Camera | D93: 8525 | E93: 红外夜视摄像机,星光级摄像机,激光夜视仪,微光摄像机,全天候监控摄像机 | F93: 安防监控,野生动物观察,军事侦察,海事夜航,边境巡逻 | G93: 最低照度(lux),红外距离(m),分辨率,防护等级,智能分析 | H93: 普通摄像机,补光灯,存储设备,云平台,电源 | I93: IR Night Vision Camera,Starlight Camera,Laser Night Vision,Low-Light Camera,All-Weather Surveillance Camera | J93: Security surveillance,Wildlife observation,Military reconnaissance,Maritime night navigation,Border patrol | K93: Minimum Illumination (lux),IR Distance (m),Resolution,IP Rating,Intelligent Analysis | L93: Day Camera,IR Illuminator,Storage,Cloud Platform,Power Supply
A94: =_xlfn.LET(_xlpm.pname,_xlfn.XLOOKUP(D94,'参考表-商品编码与name'!$A:$A,'参考表-商品编码与name'!$B:$B,""),_xlpm.seq,COUNTIF($D$2:D94,D94),_xlpm.pname&"_"&TEXT(_xlpm.seq,"00000")) -> Radio Navigation_00001 | B94: 雷达 | C94: Radar | D94: 8526 | E94: 毫米波雷达,气象雷达,测速雷达,车载雷达,机场场面监视雷达 | F94: 交通测速,航空管制,自动驾驶感知,天气预报,机场地面监控 | G94: 探测距离(m),频率(GHz),分辨率,精度,扫描方式 | H94: 激光雷达,超声波传感器,摄像头,数据处理单元,通信模块 | I94: Millimeter Wave Radar,Weather Radar,Speed Radar,Automotive Radar,ASDE Radar | J94: Traffic speed measurement,Air traffic control,ADAS,Weather forecasting,Airport surface monitoring | K94: Detection Range (m),Frequency (GHz),Resolution,Accuracy,Scanning Method | L94: LiDAR,Ultrasonic Sensor,Camera,Processing Unit,Communication Module
... A262: =_xlfn.LET(_xlpm.pname,_xlfn.XLOOKUP(D262,'参考表-商品编码与name'!$A:$A,'参考表-商品编码与name'!$B:$B,""),_xlpm.seq,COUNTIF($D$2:D262,D262),_xlpm.pname&"_"&TEXT(_xlpm.seq,"00000")) -> Tractors_00003 | B262: 农用拖拉机 | C262: Agricultural Tractor | D262: 8701 | E262: 小型农用拖拉机,中型农用拖拉机,大型农用拖拉机,四驱农用拖拉机,智能农用拖拉机 | F262: 耕地,耙地,播种,施肥,收获辅助 | G262: 马力(HP),变速箱档位,三点悬挂,液压提升,电子控制系统 | H262: 收割机,脱粒机,喷雾机,灌溉设备,农用无人机 | I262: Agricultural Tractor,Small Farm Tractor,Medium Farm Tractor,Large Farm Tractor,4WD Farm Tractor,Smart Farm Tractor | J262: Plowing,Harrowing,Seeding,Fertilizing,Harvesting support | K262: Horsepower (HP),Gearbox Gears,Three-Point Hitch,Hydraulic Lift,Electronic Control System | L262: Harvester,Thresher,Sprayer,Irrigation Equipment,Agricultural Drone
A263: =_xlfn.LET(_xlpm.pname,_xlfn.XLOOKUP(D263,'参考表-商品编码与name'!$A:$A,'参考表-商品编码与name'!$B:$B,""),_xlpm.seq,COUNTIF($D$2:D263,D263),_xlpm.pname&"_"&TEXT(_xlpm.seq,"00000")) -> Tractors_00004 | B263: 工程拖拉机 | C263: Engineering Tractor | D263: 8701 | E263: 推土拖拉机,挖掘拖拉机,装载拖拉机,平整拖拉机,多功能工程拖拉机
A264: =_xlfn.LET(_xlpm.pname,_xlfn.XLOOKUP(D264,'参考表-商品编码与name'!$A:$A,'参考表-商品编码与name'!$B:$B,""),_xlpm.seq,COUNTIF($D$2:D264,D264),_xlpm.pname&"_"&TEXT(_xlpm.seq,"00000")) -> Tractors_00005 | B264: 自动导航拖拉机 | C264: Auto-Guided Tractor | D264: 8701 | E264: 北斗/GPS导航拖拉机,智能辅助驾驶拖拉机,精准农业拖拉机,电控液压拖拉机,路径规划拖拉机,变量作业拖拉机,远程监控拖拉机,高精度定位拖拉机,网联农机,数字农田拖拉机,AI辅助决策拖拉机,环境感知拖拉机,自主避障拖拉机,智慧农场装备,电动智能拖拉机,氢燃料导航拖拉机,全天候作业平台,专业耕作导航拖拉机,农机自动驾驶系统,田间自动作业拖拉机 | F264: 监督下的无人农田作业,夜间连续耕作,精准变量施肥施药,大数据农田管理,远程集群调度 | G264: GNSS定位精度(cm),自动驾驶等级(L2/L3),感知传感器配置,通信协议(5G/V2X),电池续航时间(h) | H264: 传统手动操作拖拉机,无电子控制系统拖拉机,老旧柴油机型,非导航兼容设备 | I264: Beidou/GPS-guided tractor,smart assisted-driving tractor,precision agriculture tractor,electro-hydraulic tractor,path-planning tractor,variable-rate operation tractor,remote-monitored tractor,high-precision GNSS tractor,connected agricultural machinery,digital field tractor,AI-assisted decision tractor,environment-perception tractor,obstacle-avoidance tractor,smart farm equipment,electric smart tractor,hydrogen-fueled guided tractor,24/7 operation platform,professional cultivation guided tractor,autonomous farming system,field auto-operation tractor | J264: supervised unmanned field operation,nighttime continuous tillage,precision variable-rate application,big data farm management,remote fleet dispatch | K264: GNSS positioning accuracy (cm),autonomy level (L2/L3),perception sensor suite,communication protocol (5G/V2X),battery endurance (h) | L264: manual-operation tractor,non-electronic control tractor,old diesel model,non-GNSS compatible equipment
A265: =_xlfn.LET(_xlpm.pname,_xlfn.XLOOKUP(D265,'参考表-商品编码与name'!$A:$A,'参考表-商品编码与name'!$B:$B,""),_xlpm.seq,COUNTIF($D$2:D265,D265),_xlpm.pname&"_"&TEXT(_xlpm.seq,"00000")) -> Tractors_00006 | B265: 四轮驱动拖拉机 | C265: Four-Wheel Drive Tractor | D265: 8701 | E265: 4WD农用拖拉机,全驱农田拖拉机,高附着力拖拉机,山地作业拖拉机,大马力拖拉机,差速锁拖拉机,越野农用拖拉机,深翻重型拖拉机,高扭矩拖拉机,防滑拖拉机,强力牵引拖拉机,多功能4WD平台,果园专用拖拉机,坡地运输拖拉机,旱地耕作拖拉机,高通过性拖拉机,专业耕作拖拉机,重负荷作业拖拉机,湿滑路面拖拉机,全天候农用拖拉机 | F265: 山地梯田耕作,水田泥泞作业,重负荷深翻,坡地物料运输,湿地秸秆还田 | G265: 四轮驱动系统,差速锁类型,接地压力(kPa),轮胎花纹深度(mm),最小转弯半径(m) | H265: 手扶拖拉机,微耕机,电动园艺工具,草坪拖拉机 | I265: 4WD agricultural tractor,all-wheel-drive field tractor,high-traction tractor,hillside operation tractor,high-horsepower tractor,differential lock tractor,off-road farm tractor,heavy deep-tillage tractor,high-torque tractor,anti-slip tractor,powerful towing tractor,multi-function 4WD platform,orchard-specific tractor,slope transport tractor,dryland cultivation tractor,high-mobility tractor,professional cultivation tractor,heavy-duty operation tractor,slippery surface tractor,all-weather farm tractor | J265: terraced hillside tillage,muddy paddy field operation,heavy-duty deep plowing,slope material transport,wetland straw incorporation | K265: four-wheel drive system,differential lock type,ground pressure (kPa),tire tread depth (mm),minimum turning radius (m) | L265: walk-behind tractor,micro-tiller,electric gardening tool,lawn tractor
A266: =_xlfn.LET(_xlpm.pname,_xlfn.XLOOKUP(D266,'参考表-商品编码与name'!$A:$A,'参考表-商品编码与name'!$B:$B,""),_xlpm.seq,COUNTIF($D$2:D266,D266),_xlpm.pname&"_"&TEXT(_xlpm.seq,"00000")) -> Buses_00001 | B266: 大客车 | C266: Coach | D266: 8702 | E266: 大型客车,长途客车,城际大巴,高地板客车,十米以上客车,空调大巴,团体客车,通勤班车,卧铺客车,豪华客车,旅游大巴,客运班车,高速客车,公交大巴（非城市）,企事业单位班车 | F266: 城际客运,长途旅游,团体通勤,跨省运输,机场接送 | G266: 座位数(≥20),车身长度(m),最大总质量(kg),排放标准(国六),驱动形式(后驱/四驱) | H266: 私家轿车,SUV,出租车,货运卡车 | I266: Large Coach,Intercity Bus,Long-Distance Bus,High-Floor Bus,Over-10m Bus,Air-Conditioned Coach,Group Charter Bus,Commuter Shuttle,Sleeper Coach,Luxury Touring Bus,Tourist Coach,Passenger Liner,Express Highway Bus,Non-Urban Transit Bus,Corporate Shuttle | J266: Intercity passenger transport,Long-distance tourism,Group commuting,Cross-province travel,Airport shuttle | K266: Seating Capacity (≥20),Vehicle Length (m),Gross Vehicle Weight (kg),Emission Standard (China VI),Drive Configuration (RWD/4WD) | L266: Private Car,SUV,Taxi,Freight Truck
A267: =_xlfn.LET(_xlpm.pname,_xlfn.XLOOKUP(D267,'参考表-商品编码与name'!$A:$A,'参考表-商品编码与name'!$B:$B,""),_xlpm.seq,COUNTIF($D$2:D267,D267),_xlpm.pname&"_"&TEXT(_xlpm.seq,"00000")) -> Buses_00002 | B267: 中巴车 | C267: Minibus | D267: 8702 | E267: 小型客车,9-19座客车,短途接驳车,景区巴士,商务中巴,社区巴士,定制公交,通勤中巴,机场摆渡车(小型),校车(小型) | F267: 企事业单位通勤,景区内部交通,社区微循环,短途包车,学校接送 | G267: 核定载客(10-19人),车身长度(6-8m),转弯半径(m),燃油类型(柴油/汽油/电) | H267: 大型公交车,私家车,重型卡车 | I267: Small Bus,9-19 Seat Bus,Short-Haul Shuttle,Resort Minibus,Business Minibus,Community Circulator,Customized Micro-Transit,Commuter Minibus,Small Airport Shuttle,Compact School Bus | J267: Corporate commuting,Resort internal transport,Community micro-circulation,Short-distance charter,School pick-up/drop-off | K267: Approved Passenger Capacity (10-19),Body Length (6-8m),Turning Radius (m),Fuel Type (Diesel/Gasoline/Electric) | L267: Large Transit Bus,Private Car,Heavy-Duty Truck
A268: =_xlfn.LET(_xlpm.pname,_xlfn.XLOOKUP(D268,'参考表-商品编码与name'!$A:$A,'参考表-商品编码与name'!$B:$B,""),_xlpm.seq,COUNTIF($D$2:D268,D268),_xlpm.pname&"_"&TEXT(_xlpm.seq,"00000")) -> Buses_00003 | B268: 城市公交车 | C268: Urban Bus | D268: 8702 | E268: 低地板公交,全电动公交,插电混动公交,氢能源公交,无障碍公交,智能调度公交,空调公交车,快速公交(BRT),社区微循环公交,主干线公交 | F268: 城市日常公共交通运营,地铁接驳运输,社区短途出行,高峰通勤疏导,大型活动客流疏散 | G268: 额定载客量(人),电池容量(kWh),充电接口类型,最小转弯直径(m),服务寿命(年) | H268: 长途卧铺车,旅游包车,校车,货运厢式车 | I268: Low-Floor City Bus,Full Electric Bus,Plug-in Hybrid Bus,Hydrogen-Powered Bus,Accessible Bus,Smart-Scheduled Bus,Air-Conditioned City Bus,BRT Vehicle,Community Micro-Circulation Bus,Mainline Transit Bus | J268: Daily urban public transport operation,Subway feeder service,Community short-distance travel,Peak-hour commuting crowd management,Major event passenger evacuation | K268: Rated Passenger Capacity (persons),Battery Capacity (kWh),Charging Interface Type,Minimum Turning Diameter (m),Service Life (years) | L268: Long-Distance Sleeper Coach,Tour Charter Bus,School Bus,Cargo Van
A269: =_xlfn.LET(_xlpm.pname,_xlfn.XLOOKUP(D269,'参考表-商品编码与name'!$A:$A,'参考表-商品编码与name'!$B:$B,""),_xlpm.seq,COUNTIF($D$2:D269,D269),_xlpm.pname&"_"&TEXT(_xlpm.seq,"00000")) -> Buses_00004 | B269: 旅游客车 | C269: Tourist Coach | D269: 8702 | E269: 团体旅游大巴,豪华观光车,空调旅游车,高速客运车,跨境旅游巴士,全景天窗客车,LED夜景车,智能导览旅游巴士,新能源旅游车,国产旅游客车 | F269: 跨省旅游,团队出行,景区定点接驳,大型会展人员运输,节假日包车 | G269: 行李舱容积(m³),座椅舒适度等级,续航里程(km),安全逃生通道数量,多媒体娱乐系统 | H269: 城市通勤公交,校车,普通单层大巴,货运车 | I269: Group Touring Coach,Luxury Sightseeing Bus,Air-Conditioned Tour Bus,Express Touring Bus,Cross-Border Tour Bus,Panoramic Roof Coach,LED Night-View Bus,Smart Guided Tour Bus,New Energy Tour Bus,Domestic Touring Coach | J269: Inter-provincial tourism,Group travel,Resort fixed-point shuttle,Major exhibition staff transport,Holiday charter service | K269: Luggage Compartment Volume (m³),Seat Comfort Rating,Driving Range (km),Emergency Exit Count,Onboard Entertainment System | L269: Urban Commuter Bus,School Bus,Standard Single-Deck Bus,Freight Vehicle
A270: =_xlfn.LET(_xlpm.pname,_xlfn.XLOOKUP(D270,'参考表-商品编码与name'!$A:$A,'参考表-商品编码与name'!$B:$B,""),_xlpm.seq,COUNTIF($D$2:D270,D270),_xlpm.pname&"_"&TEXT(_xlpm.seq,"00000")) -> Buses_00005 | B270: 校车 | C270: School Bus | D270: 8702 | E270: 中小学生专用校车,黄色校车,安全校车,国标校车,新能源校车,低地板校车,乡村校车,城市校车,定制校车,智能校车 | F270: 学校学生接送,教育机构通勤,特殊教育出行,偏远地区学生运输 | G270: 防撞结构,停车指示牌,限速装置,车内监控系统,学生上下车提醒 | H270: 普通客运车,私家车,货运车,出租车 | I270: Dedicated School Bus,Yellow School Bus,Safety-Enhanced School Bus,GB-Standard School Bus,Electric School Bus,Low-Floor School Bus,Rural School Bus,Urban School Bus,Custom School Bus,Smart School Bus | J270: School student transportation,Educational institution commuting,Special needs education travel,Remote area student transport | K270: Crash-Resistant Structure,Stop Sign Arm,Speed Limiter,Onboard Monitoring System,Student Boarding/Alighting Alert | L270: Regular Passenger Bus,Private Car,Freight Vehicle,Taxi
A271: =_xlfn.LET(_xlpm.pname,_xlfn.XLOOKUP(D271,'参考表-商品编码与name'!$A:$A,'参考表-商品编码与name'!$B:$B,""),_xlpm.seq,COUNTIF($D$2:D271,D271),_xlpm.pname&"_"&TEXT(_xlpm.seq,"00000")) -> Cars_00001 | B271: 轿车 | C271: Sedan | D271: 8703 | E271: 三厢轿车,家用轿车,公务轿车,经济型轿车,中级轿车,高级轿车,燃油轿车,新能源轿车,纯电轿车,混动轿车 | F271: 家庭日常出行,公务接待,网约车运营,租赁用车,城市通勤 | G271: 发动机排量(L),座位数(5座),驱动方式(前驱/后驱),油耗(L/100km),续航里程(km) | H271: 大客车,中巴车,货车,摩托车 | I271: Three-Box Sedan,Family Sedan,Executive Sedan,Economy Sedan,Compact/Midsize/Luxury Sedan,Fuel Sedan,New Energy Sedan,BEV Sedan,Hybrid Sedan | J271: Daily family travel,Official reception,Ride-hailing service,Rental fleet,Urban commuting | K271: Engine Displacement (L),Seating Capacity (5),Drive Layout (FWD/RWD),Fuel Consumption (L/100km),Driving Range (km) | L271: Coach,Minibus,Truck,Motorcycle
A272: =_xlfn.LET(_xlpm.pname,_xlfn.XLOOKUP(D272,'参考表-商品编码与name'!$A:$A,'参考表-商品编码与name'!$B:$B,""),_xlpm.seq,COUNTIF($D$2:D272,D272),_xlpm.pname&"_"&TEXT(_xlpm.seq,"00000")) -> Cars_00002 | B272: SUV | C272: SUV | D272: 8703 | E272: 运动型多用途车,城市SUV,越野SUV,紧凑型SUV,中大型SUV,七座SUV,新能源SUV,纯电SUV,混动SUV,高性能SUV | F272: 家庭出游,轻度越野,城市代步,自驾旅行,多孩家庭用车 | G272: 离地间隙(mm),四驱系统,座椅布局(5/7座),后备箱容积(L),智能驾驶等级 | H272: 大客车,货车,摩托车,皮卡 | I272: Sport Utility Vehicle,Urban SUV,Off-Road SUV,Compact SUV,Midsize/Large SUV,7-Seater SUV,New Energy SUV,BEV SUV,Hybrid SUV,Performance SUV | J272: Family road trips,Light off-roading,Urban daily driving,Self-driving travel,Multi-child family use | K272: Ground Clearance (mm),Four-Wheel Drive System,Seating Configuration (5/7),Trunk Volume (L),ADAS Level | L272: Coach,Truck,Motorcycle,Pickup Truck
A273: =_xlfn.LET(_xlpm.pname,_xlfn.XLOOKUP(D273,'参考表-商品编码与name'!$A:$A,'参考表-商品编码与name'!$B:$B,""),_xlpm.seq,COUNTIF($D$2:D273,D273),_xlpm.pname&"_"&TEXT(_xlpm.seq,"00000")) -> Cars_00003 | B273: MPV | C273: MPV | D273: 8703 | E273: 多用途乘用车,家用MPV,商务MPV,七座MPV,中大型MPV,新能源MPV,纯电MPV,滑门MPV,高顶MPV,豪华MPV | F273: 多人口家庭出行,商务接待,机场接送,租赁服务,团体短途出行 | G273: 第二排独立座椅,侧滑门,轴距(mm),第三排空间,舒适性配置 | H273: 轿车,SUV,货车,摩托车 | I273: Multi-Purpose Vehicle,Family MPV,Business MPV,7-Seater MPV,Midsize/Large MPV,New Energy MPV,BEV MPV,Sliding-Door MPV,High-Roof MPV,Luxury MPV | J273: Large-family travel,Business hospitality,Airport transfer,Rental service,Group short-haul trips | K273: Second-Row Captain Seats,Sliding Doors,Wheelbase (mm),Third-Row Legroom,Comfort Features | L273: Sedan,SUV,Truck,Motorcycle
A274: =_xlfn.LET(_xlpm.pname,_xlfn.XLOOKUP(D274,'参考表-商品编码与name'!$A:$A,'参考表-商品编码与name'!$B:$B,""),_xlpm.seq,COUNTIF($D$2:D274,D274),_xlpm.pname&"_"&TEXT(_xlpm.seq,"00000")) -> Cars_00004 | B274: 跑车 | C274: Sports Car | D274: 8703 | E274: 双门跑车,敞篷跑车,高性能跑车,超跑,轿跑车,电动跑车,入门级跑车,经典跑车,赛道跑车,限量版跑车 | F274: 个人驾驶乐趣,收藏展示,赛道日活动,高端社交场合,品牌体验 | G274: 0-100km/h加速(s),最高时速(km/h),发动机布局(中置/后置),空气动力学设计,轻量化材料 | H274: 家用轿车,MPV,SUV,货车 | I274: Two-Door Sports Car,Convertible,High-Performance Coupe,Supercar,Gran Turismo,Electric Sports Car,Entry-Level Sports Car,Classic Sports Car,Track-Day Car,Limited Edition | J274: Personal driving pleasure,Collection display,Track day events,High-end social occasions,Brand experience | K274: 0-100 km/h Acceleration (s),Top Speed (km/h),Engine Layout (Mid/Rear),Aerodynamic Design,Lightweight Materials | L274: Family Sedan,MPV,SUV,Truck
...

Sheet product_master 
A1: product_id | B1: std_name_cn | C1: std_name_en | D1: hs_code | E1: category_l1zh | F1: category_l2zh | G1: status(active/inactive)
A2: =_xlfn.LET(_xlpm.pname,_xlfn.XLOOKUP(D2,'参考表-商品编码与name'!$A:$A,'参考表-商品编码与name'!$B:$B,""),_xlpm.seq,COUNTIF($D$2:D2,D2),_xlpm.pname&"_"&TEXT(_xlpm.seq,"00000")) -> Electric Motors_00001 | B2: 异步电动机 | C2: Asynchronous Motor | D2: 8501
A3: =_xlfn.LET(_xlpm.pname,_xlfn.XLOOKUP(D3,'参考表-商品编码与name'!$A:$A,'参考表-商品编码与name'!$B:$B,""),_xlpm.seq,COUNTIF($D$2:D3,D3),_xlpm.pname&"_"&TEXT(_xlpm.seq,"00000")) -> Electric Motors_00002 | B3: 直流电动机 | C3: DC Motor | D3: 8501
A4: =_xlfn.LET(_xlpm.pname,_xlfn.XLOOKUP(D4,'参考表-商品编码与name'!$A:$A,'参考表-商品编码与name'!$B:$B,""),_xlpm.seq,COUNTIF($D$2:D4,D4),_xlpm.pname&"_"&TEXT(_xlpm.seq,"00000")) -> Electric Motors_00003 | B4: 伺服电机 | C4: Servo Motor | D4: 8501
A5: =_xlfn.LET(_xlpm.pname,_xlfn.XLOOKUP(D5,'参考表-商品编码与name'!$A:$A,'参考表-商品编码与name'!$B:$B,""),_xlpm.seq,COUNTIF($D$2:D5,D5),_xlpm.pname&"_"&TEXT(_xlpm.seq,"00000")) -> Electric Motors_00004 | B5: 步进电机 | C5: Stepper Motor | D5: 8501
A6: =_xlfn.LET(_xlpm.pname,_xlfn.XLOOKUP(D6,'参考表-商品编码与name'!$A:$A,'参考表-商品编码与name'!$B:$B,""),_xlpm.seq,COUNTIF($D$2:D6,D6),_xlpm.pname&"_"&TEXT(_xlpm.seq,"00000")) -> Electric Motors_00005 | B6: 发电机 | C6: Generator | D6: 8501
A7: =_xlfn.LET(_xlpm.pname,_xlfn.XLOOKUP(D7,'参考表-商品编码与name'!$A:$A,'参考表-商品编码与name'!$B:$B,""),_xlpm.seq,COUNTIF($D$2:D7,D7),_xlpm.pname&"_"&TEXT(_xlpm.seq,"00000")) -> Generating Sets_00001 | B7: 柴油发电机组 | C7: Diesel Generator Set | D7: 8502
A8: =_xlfn.LET(_xlpm.pname,_xlfn.XLOOKUP(D8,'参考表-商品编码与name'!$A:$A,'参考表-商品编码与name'!$B:$B,""),_xlpm.seq,COUNTIF($D$2:D8,D8),_xlpm.pname&"_"&TEXT(_xlpm.seq,"00000")) -> Generating Sets_00002 | B8: 汽油发电机组 | C8: Gasoline Generator Set | D8: 8502
A9: =_xlfn.LET(_xlpm.pname,_xlfn.XLOOKUP(D9,'参考表-商品编码与name'!$A:$A,'参考表-商品编码与name'!$B:$B,""),_xlpm.seq,COUNTIF($D$2:D9,D9),_xlpm.pname&"_"&TEXT(_xlpm.seq,"00000")) -> Motor Parts_00001 | B9: 电机定子 | C9: Stator | D9: 8503
A10: =_xlfn.LET(_xlpm.pname,_xlfn.XLOOKUP(D10,'参考表-商品编码与name'!$A:$A,'参考表-商品编码与name'!$B:$B,""),_xlpm.seq,COUNTIF($D$2:D10,D10),_xlpm.pname&"_"&TEXT(_xlpm.seq,"00000")) -> Motor Parts_00002 | B10: 电机转子 | C10: Rotor | D10: 8503
A11: =_xlfn.LET(_xlpm.pname,_xlfn.XLOOKUP(D11,'参考表-商品编码与name'!$A:$A,'参考表-商品编码与name'!$B:$B,""),_xlpm.seq,COUNTIF($D$2:D11,D11),_xlpm.pname&"_"&TEXT(_xlpm.seq,"00000")) -> Motor Parts_00003 | B11: 电刷 | C11: Carbon Brush | D11: 8503
A12: =_xlfn.LET(_xlpm.pname,_xlfn.XLOOKUP(D12,'参考表-商品编码与name'!$A:$A,'参考表-商品编码与name'!$B:$B,""),_xlpm.seq,COUNTIF($D$2:D12,D12),_xlpm.pname&"_"&TEXT(_xlpm.seq,"00000")) -> Transformers_00001 | B12: 电力变压器 | C12: Power Transformer | D12: 8504
A13: =_xlfn.LET(_xlpm.pname,_xlfn.XLOOKUP(D13,'参考表-商品编码与name'!$A:$A,'参考表-商品编码与name'!$B:$B,""),_xlpm.seq,COUNTIF($D$2:D13,D13),_xlpm.pname&"_"&TEXT(_xlpm.seq,"00000")) -> Transformers_00002 | B13: 开关电源 | C13: Switching Power Supply | D13: 8504
... A340: =_xlfn.LET(_xlpm.pname,_xlfn.XLOOKUP(D340,'参考表-商品编码与name'!$A:$A,'参考表-商品编码与name'!$B:$B,""),_xlpm.seq,COUNTIF($D$2:D340,D340),_xlpm.pname&"_"&TEXT(_xlpm.seq,"00000")) -> Trailers_00005 | B340: 低平板半挂车 | C340: Lowboy Semi-Trailer | D340: 8716

Sheet product_terms
A1: id | B1: product_id | C1: term | D1: lang | E1: term_type(synonym / technical / scenario / exclusion) | F1: weight | G1: penalty

Sheet product_industry
A1: product_id | B1: industry_id | C1: weight

Sheet 参考表-商品编码与name
A1: 商品编码 | B1: Class Name
A2: 8501 | B2: Electric Motors
A3: 8502 | B3: Generating Sets
A4: 8503 | B4: Motor Parts
A5: 8504 | B5: Transformers
A6: 8505 | B6: Magnets
A7: 8506 | B7: Dry Batteries
A8: 8507 | B8: Accumulators
A9: 8508 | B9: Vacuum Cleaners
A10: 8509 | B10: Household Appliances
A11: 8510 | B11: Hair Clippers
A12: 8511 | B12: Ignition & Starting Devices
A13: 8512 | B13: Vehicle Lighting
... A74: 8716 | B74: Trailers

Sheet 参考表-catagory
A1: category_l1_en | B1: category_l1_zh | C1: category_l2_en | D1: category_l2_zh
A2: Agriculture & Primary Food | B2: 农产品 & 初级食品 | C2: Grains | D2: 谷物类
A3: Agriculture & Primary Food | B3: 农产品 & 初级食品 | C3: Oilseeds | D3: 油籽类
A4: Agriculture & Primary Food | B4: 农产品 & 初级食品 | C4: Fresh Fruits & Vegetables | D4: 新鲜蔬果
A5: Agriculture & Primary Food | B5: 农产品 & 初级食品 | C5: Aquatic Products | D5: 水产品
A6: Agriculture & Primary Food | B6: 农产品 & 初级食品 | C6: Raw Meat | D6: 肉类原料
A7: Agriculture & Primary Food | B7: 农产品 & 初级食品 | C7: Feed Ingredients | D7: 饲料原料
A9: Processed Food & FMCG | B9: 食品加工 & 快消食品 | C9: Dairy Products | D9: 乳制品
A10: Processed Food & FMCG | B10: 食品加工 & 快消食品 | C10: Snack Foods | D10: 休闲食品
A11: Processed Food & FMCG | B11: 食品加工 & 快消食品 | C11: Condiments | D11: 调味品
A12: Processed Food & FMCG | B12: 食品加工 & 快消食品 | C12: Beverages | D12: 饮料类
A13: Processed Food & FMCG | B13: 食品加工 & 快消食品 | C13: Canned Foods | D13: 罐头食品
... A75: Consumer Goods & Others | B75: 消费品 & 其他制成品 | C75: Daily Necessities | D75: 日用百货
